Workbook

Sheet README
A1: NBA 2024-25 Head-to-Head Workbook
A2: What is in this file | B2: Complete team-vs-team head-to-head results for the 2024-25 NBA regular season, for all 30 teams.
A3: How to read it | B3: Use 'Series_Matrix' for W-L by row team vs column opponent; 'Detail' for one row per team/opponent; 'Games_Raw' for the source game list.
A4: Season scope | B4: Regular season only (82 games per team).
A5: Data source URL | B5: https://fixturedownload.com/download/nba-2024-UTC.csv
A6: Source page URL | B6: https://fixturedownload.com/results/nba-2024
A7: Official NBA schedule article | B7: https://www.nba.com/news/2024-25-nba-regular-season-schedule
A8: Excluded from totals | B8: The source file contains one extra Bucks-Thunder neutral-site Emirates NBA Cup Championship game. It is flagged as 'No' in Games_Raw > Is Regular Season and excluded from all head-to-head totals.
A9: Validation | B9: The workbook formulas produce 82 regular-season games for every team after that exclusion.

Sheet Games_Raw
A1: Match Number | B1: Round Number | C1: Date/Time (UTC) | D1: Location | E1: Home Team | F1: Away Team | G1: Home Score | H1: Away Score | I1: Winner | J1: Loser | K1: Is Regular Season | L1: Notes | M1: Source URL
A2: 1 | B2: 1 | C2: 22/10/2024 23:30 | D2: TD Garden | E2: Boston Celtics | F2: New York Knicks | G2: 132 | H2: 109 | I2: Boston Celtics | J2: New York Knicks | K2: Yes | M2: https://fixturedownload.com/download/nba-2024-UTC.csv
A3: 2 | B3: 1 | C3: 23/10/2024 02:00 | D3: Crypto.com Arena | E3: Los Angeles Lakers | F3: Minnesota Timberwolves | G3: 110 | H3: 103 | I3: Los Angeles Lakers | J3: Minnesota Timberwolves | K3: Yes | M3: https://fixturedownload.com/download/nba-2024-UTC.csv
A4: 3 | B4: 1 | C4: 23/10/2024 23:00 | D4: Little Caesars Arena | E4: Detroit Pistons | F4: Indiana Pacers | G4: 109 | H4: 115 | I4: Indiana Pacers | J4: Detroit Pistons | K4: Yes | M4: https://fixturedownload.com/download/nba-2024-UTC.csv
A5: 4 | B5: 1 | C5: 23/10/2024 23:30 | D5: State Farm Arena | E5: Atlanta Hawks | F5: Brooklyn Nets | G5: 120 | H5: 116 | I5: Atlanta Hawks | J5: Brooklyn Nets | K5: Yes | M5: https://fixturedownload.com/download/nba-2024-UTC.csv
A6: 5 | B6: 1 | C6: 23/10/2024 23:30 | D6: Kaseya Center | E6: Miami Heat | F6: Orlando Magic | G6: 97 | H6: 116 | I6: Orlando Magic | J6: Miami Heat | K6: Yes | M6: https://fixturedownload.com/download/nba-2024-UTC.csv
A7: 6 | B7: 1 | C7: 23/10/2024 23:30 | D7: Wells Fargo Center | E7: Philadelphia 76ers | F7: Milwaukee Bucks | G7: 109 | H7: 124 | I7: Milwaukee Bucks | J7: Philadelphia 76ers | K7: Yes | M7: https://fixturedownload.com/download/nba-2024-UTC.csv
A8: 7 | B8: 1 | C8: 23/10/2024 23:30 | D8: Scotiabank Arena | E8: Toronto Raptors | F8: Cleveland Cavaliers | G8: 106 | H8: 136 | I8: Cleveland Cavaliers | J8: Toronto Raptors | K8: Yes | M8: https://fixturedownload.com/download/nba-2024-UTC.csv
A9: 8 | B9: 1 | C9: 24/10/2024 00:00 | D9: Toyota Center | E9: Houston Rockets | F9: Charlotte Hornets | G9: 105 | H9: 110 | I9: Charlotte Hornets | J9: Houston Rockets | K9: Yes | M9: https://fixturedownload.com/download/nba-2024-UTC.csv
A10: 9 | B10: 1 | C10: 24/10/2024 00:00 | D10: Smoothie King Center | E10: New Orleans Pelicans | F10: Chicago Bulls | G10: 123 | H10: 111 | I10: New Orleans Pelicans | J10: Chicago Bulls | K10: Yes | M10: https://fixturedownload.com/download/nba-2024-UTC.csv
A11: 10 | B11: 1 | C11: 24/10/2024 01:00 | D11: Delta Center | E11: Utah Jazz | F11: Memphis Grizzlies | G11: 124 | H11: 126 | I11: Memphis Grizzlies | J11: Utah Jazz | K11: Yes | M11: https://fixturedownload.com/download/nba-2024-UTC.csv
A12: 11 | B12: 1 | C12: 24/10/2024 02:00 | D12: Intuit Dome | E12: LA Clippers | F12: Phoenix Suns | G12: 113 | H12: 116 | I12: Phoenix Suns | J12: LA Clippers | K12: Yes | M12: https://fixturedownload.com/download/nba-2024-UTC.csv
A13: 12 | B13: 1 | C13: 24/10/2024 02:00 | D13: Moda Center | E13: Portland Trail Blazers | F13: Golden State Warriors | G13: 104 | H13: 140 | I13: Golden State Warriors | J13: Portland Trail Blazers | K13: Yes | M13: https://fixturedownload.com/download/nba-2024-UTC.csv
... A390: 1226 | B390: 8 | C390: 17/12/2024 03:30 | D390: Intuit Dome | E390: LA Clippers | F390: Utah Jazz | G390: 144 | H390: 107 | I390: LA Clippers | J390: Utah Jazz | K390: Yes | M390: https://fixturedownload.com/download/nba-2024-UTC.csv
A391: 1231 | B391: 8 | C391: 18/12/2024 01:30 | D391: T-Mobile Arena | E391: Oklahoma City Thunder | F391: Milwaukee Bucks | G391: 81 | H391: 97 | I391: Milwaukee Bucks | J391: Oklahoma City Thunder | K391: No | L391: Emirates NBA Cup Championship (excluded from regular-season head-to-head totals) | M391: https://fixturedownload.com/download/nba-2024-UTC.csv
A392: 360 | B392: 8 | C392: 20/12/2024 00:00 | D392: Little Caesars Arena | E392: Detroit Pistons | F392: Utah Jazz | G392: 119 | H392: 126 | I392: Utah Jazz | J392: Detroit Pistons | K392: Yes | M392: https://fixturedownload.com/download/nba-2024-UTC.csv
A393: 361 | B393: 8 | C393: 20/12/2024 00:00 | D393: Kia Center | E393: Orlando Magic | F393: Oklahoma City Thunder | G393: 99 | H393: 105 | I393: Oklahoma City Thunder | J393: Orlando Magic | K393: Yes | M393: https://fixturedownload.com/download/nba-2024-UTC.csv
A394: 362 | B394: 8 | C394: 20/12/2024 00:00 | D394: Capital One Arena | E394: Washington Wizards | F394: Charlotte Hornets | G394: 123 | H394: 114 | I394: Washington Wizards | J394: Charlotte Hornets | K394: Yes | M394: https://fixturedownload.com/download/nba-2024-UTC.csv
A395: 363 | B395: 8 | C395: 20/12/2024 00:30 | D395: TD Garden | E395: Boston Celtics | F395: Chicago Bulls | G395: 108 | H395: 117 | I395: Chicago Bulls | J395: Boston Celtics | K395: Yes | M395: https://fixturedownload.com/download/nba-2024-UTC.csv
A396: 364 | B396: 8 | C396: 20/12/2024 00:30 | D396: Scotiabank Arena | E396: Toronto Raptors | F396: Brooklyn Nets | G396: 94 | H396: 101 | I396: Brooklyn Nets | J396: Toronto Raptors | K396: Yes | M396: https://fixturedownload.com/download/nba-2024-UTC.csv
A397: 365 | B397: 8 | C397: 20/12/2024 01:00 | D397: Toyota Center | E397: Houston Rockets | F397: New Orleans Pelicans | G397: 133 | H397: 113 | I397: Houston Rockets | J397: New Orleans Pelicans | K397: Yes | M397: https://fixturedownload.com/download/nba-2024-UTC.csv
A398: 366 | B398: 8 | C398: 20/12/2024 01:00 | D398: FedExForum | E398: Memphis Grizzlies | F398: Golden State Warriors | G398: 144 | H398: 93 | I398: Memphis Grizzlies | J398: Golden State Warriors | K398: Yes | M398: https://fixturedownload.com/download/nba-2024-UTC.csv
A399: 370 | B399: 8 | C399: 20/12/2024 01:00 | D399: Frost Bank Center | E399: San Antonio Spurs | F399: Atlanta Hawks | G399: 133 | H399: 126 | I399: San Antonio Spurs | J399: Atlanta Hawks | K399: Yes | M399: https://fixturedownload.com/download/nba-2024-UTC.csv
A400: 368 | B400: 8 | C400: 20/12/2024 01:30 | D400: American Airlines Center | E400: Dallas Mavericks | F400: LA Clippers | G400: 95 | H400: 118 | I400: LA Clippers | J400: Dallas Mavericks | K400: Yes | M400: https://fixturedownload.com/download/nba-2024-UTC.csv
A401: 369 | B401: 8 | C401: 20/12/2024 02:00 | D401: PHX Arena | E401: Phoenix Suns | F401: Indiana Pacers | G401: 111 | H401: 120 | I401: Indiana Pacers | J401: Phoenix Suns | K401: Yes | M401: https://fixturedownload.com/download/nba-2024-UTC.csv
A402: 367 | B402: 8 | C402: 20/12/2024 02:30 | D402: Target Center | E402: Minnesota Timberwolves | F402: New York Knicks | G402: 107 | H402: 133 | I402: New York Knicks | J402: Minnesota Timberwolves | K402: Yes | M402: https://fixturedownload.com/download/nba-2024-UTC.csv
A403: 371 | B403: 8 | C403: 20/12/2024 03:00 | D403: Moda Center | E403: Portland Trail Blazers | F403: Denver Nuggets | G403: 126 | H403: 124 | I403: Portland Trail Blazers | J403: Denver Nuggets | K403: Yes | M403: https://fixturedownload.com/download/nba-2024-UTC.csv
... A1232: 1200 | B1232: 23 | C1232: 13/04/2025 19:30 | D1232: Golden 1 Center | E1232: Sacramento Kings | F1232: Phoenix Suns | G1232: 109 | H1232: 98 | I1232: Sacramento Kings | J1232: Phoenix Suns | K1232: Yes | M1232: https://fixturedownload.com/download/nba-2024-UTC.csv

Sheet Validation
A1: Team | B1: Regular-Season Games | C1: Wins | D1: Losses | E1: Wins + Losses | F1: Check
A2: Atlanta Hawks | B2: =COUNTIFS(Games_Raw!$K$2:$K$1232,"Yes",Games_Raw!$E$2:$E$1232,"Atlanta Hawks")+COUNTIFS(Games_Raw!$K$2:$K$1232,"Yes",Games_Raw!$F$2:$F$1232,"Atlanta Hawks") -> 82 | C2: =COUNTIFS(Games_Raw!$K$2:$K$1232,"Yes",Games_Raw!$I$2:$I$1232,"Atlanta Hawks") -> 40 | D2: =COUNTIFS(Games_Raw!$K$2:$K$1232,"Yes",Games_Raw!$J$2:$J$1232,"Atlanta Hawks") -> 42 | E2: =C2+D2 -> 82 | F2: =IF(AND(B2=82,E2=82),"OK","CHECK") -> OK
A3: Boston Celtics | B3: =COUNTIFS(Games_Raw!$K$2:$K$1232,"Yes",Games_Raw!$E$2:$E$1232,"Boston Celtics")+COUNTIFS(Games_Raw!$K$2:$K$1232,"Yes",Games_Raw!$F$2:$F$1232,"Boston Celtics") -> 82 | C3: =COUNTIFS(Games_Raw!$K$2:$K$1232,"Yes",Games_Raw!$I$2:$I$1232,"Boston Celtics") -> 61 | D3: =COUNTIFS(Games_Raw!$K$2:$K$1232,"Yes",Games_Raw!$J$2:$J$1232,"Boston Celtics") -> 21 | E3: =C3+D3 -> 82 | F3: =IF(AND(B3=82,E3=82),"OK","CHECK") -> OK
A4: Brooklyn Nets | B4: =COUNTIFS(Games_Raw!$K$2:$K$1232,"Yes",Games_Raw!$E$2:$E$1232,"Brooklyn Nets")+COUNTIFS(Games_Raw!$K$2:$K$1232,"Yes",Games_Raw!$F$2:$F$1232,"Brooklyn Nets") -> 82 | C4: =COUNTIFS(Games_Raw!$K$2:$K$1232,"Yes",Games_Raw!$I$2:$I$1232,"Brooklyn Nets") -> 26 | D4: =COUNTIFS(Games_Raw!$K$2:$K$1232,"Yes",Games_Raw!$J$2:$J$1232,"Brooklyn Nets") -> 56 | E4: =C4+D4 -> 82 | F4: =IF(AND(B4=82,E4=82),"OK","CHECK") -> OK
A5: Charlotte Hornets | B5: =COUNTIFS(Games_Raw!$K$2:$K$1232,"Yes",Games_Raw!$E$2:$E$1232,"Charlotte Hornets")+COUNTIFS(Games_Raw!$K$2:$K$1232,"Yes",Games_Raw!$F$2:$F$1232,"Charlotte Hornets") -> 82 | C5: =COUNTIFS(Games_Raw!$K$2:$K$1232,"Yes",Games_Raw!$I$2:$I$1232,"Charlotte Hornets") -> 19 | D5: =COUNTIFS(Games_Raw!$K$2:$K$1232,"Yes",Games_Raw!$J$2:$J$1232,"Charlotte Hornets") -> 63 | E5: =C5+D5 -> 82 | F5: =IF(AND(B5=82,E5=82),"OK","CHECK") -> OK
A6: Chicago Bulls | B6: =COUNTIFS(Games_Raw!$K$2:$K$1232,"Yes",Games_Raw!$E$2:$E$1232,"Chicago Bulls")+COUNTIFS(Games_Raw!$K$2:$K$1232,"Yes",Games_Raw!$F$2:$F$1232,"Chicago Bulls") -> 82 | C6: =COUNTIFS(Games_Raw!$K$2:$K$1232,"Yes",Games_Raw!$I$2:$I$1232,"Chicago Bulls") -> 39 | D6: =COUNTIFS(Games_Raw!$K$2:$K$1232,"Yes",Games_Raw!$J$2:$J$1232,"Chicago Bulls") -> 43 | E6: =C6+D6 -> 82 | F6: =IF(AND(B6=82,E6=82),"OK","CHECK") -> OK
A7: Cleveland Cavaliers | B7: =COUNTIFS(Games_Raw!$K$2:$K$1232,"Yes",Games_Raw!$E$2:$E$1232,"Cleveland Cavaliers")+COUNTIFS(Games_Raw!$K$2:$K$1232,"Yes",Games_Raw!$F$2:$F$1232,"Cleveland Cavaliers") -> 82 | C7: =COUNTIFS(Games_Raw!$K$2:$K$1232,"Yes",Games_Raw!$I$2:$I$1232,"Cleveland Cavaliers") -> 64 | D7: =COUNTIFS(Games_Raw!$K$2:$K$1232,"Yes",Games_Raw!$J$2:$J$1232,"Cleveland Cavaliers") -> 18 | E7: =C7+D7 -> 82 | F7: =IF(AND(B7=82,E7=82),"OK","CHECK") -> OK
A8: Dallas Mavericks | B8: =COUNTIFS(Games_Raw!$K$2:$K$1232,"Yes",Games_Raw!$E$2:$E$1232,"Dallas Mavericks")+COUNTIFS(Games_Raw!$K$2:$K$1232,"Yes",Games_Raw!$F$2:$F$1232,"Dallas Mavericks") -> 82 | C8: =COUNTIFS(Games_Raw!$K$2:$K$1232,"Yes",Games_Raw!$I$2:$I$1232,"Dallas Mavericks") -> 39 | D8: =COUNTIFS(Games_Raw!$K$2:$K$1232,"Yes",Games_Raw!$J$2:$J$1232,"Dallas Mavericks") -> 43 | E8: =C8+D8 -> 82 | F8: =IF(AND(B8=82,E8=82),"OK","CHECK") -> OK
A9: Denver Nuggets | B9: =COUNTIFS(Games_Raw!$K$2:$K$1232,"Yes",Games_Raw!$E$2:$E$1232,"Denver Nuggets")+COUNTIFS(Games_Raw!$K$2:$K$1232,"Yes",Games_Raw!$F$2:$F$1232,"Denver Nuggets") -> 82 | C9: =COUNTIFS(Games_Raw!$K$2:$K$1232,"Yes",Games_Raw!$I$2:$I$1232,"Denver Nuggets") -> 50 | D9: =COUNTIFS(Games_Raw!$K$2:$K$1232,"Yes",Games_Raw!$J$2:$J$1232,"Denver Nuggets") -> 32 | E9: =C9+D9 -> 82 | F9: =IF(AND(B9=82,E9=82),"OK","CHECK") -> OK
A10: Detroit Pistons | B10: =COUNTIFS(Games_Raw!$K$2:$K$1232,"Yes",Games_Raw!$E$2:$E$1232,"Detroit Pistons")+COUNTIFS(Games_Raw!$K$2:$K$1232,"Yes",Games_Raw!$F$2:$F$1232,"Detroit Pistons") -> 82 | C10: =COUNTIFS(Games_Raw!$K$2:$K$1232,"Yes",Games_Raw!$I$2:$I$1232,"Detroit Pistons") -> 44 | D10: =COUNTIFS(Games_Raw!$K$2:$K$1232,"Yes",Games_Raw!$J$2:$J$1232,"Detroit Pistons") -> 38 | E10: =C10+D10 -> 82 | F10: =IF(AND(B10=82,E10=82),"OK","CHECK") -> OK
A11: Golden State Warriors | B11: =COUNTIFS(Games_Raw!$K$2:$K$1232,"Yes",Games_Raw!$E$2:$E$1232,"Golden State Warriors")+COUNTIFS(Games_Raw!$K$2:$K$1232,"Yes",Games_Raw!$F$2:$F$1232,"Golden State Warriors") -> 82 | C11: =COUNTIFS(Games_Raw!$K$2:$K$1232,"Yes",Games_Raw!$I$2:$I$1232,"Golden State Warriors") -> 48 | D11: =COUNTIFS(Games_Raw!$K$2:$K$1232,"Yes",Games_Raw!$J$2:$J$1232,"Golden State Warriors") -> 34 | E11: =C11+D11 -> 82 | F11: =IF(AND(B11=82,E11=82),"OK","CHECK") -> OK
A12: Houston Rockets | B12: =COUNTIFS(Games_Raw!$K$2:$K$1232,"Yes",Games_Raw!$E$2:$E$1232,"Houston Rockets")+COUNTIFS(Games_Raw!$K$2:$K$1232,"Yes",Games_Raw!$F$2:$F$1232,"Houston Rockets") -> 82 | C12: =COUNTIFS(Games_Raw!$K$2:$K$1232,"Yes",Games_Raw!$I$2:$I$1232,"Houston Rockets") -> 52 | D12: =COUNTIFS(Games_Raw!$K$2:$K$1232,"Yes",Games_Raw!$J$2:$J$1232,"Houston Rockets") -> 30 | E12: =C12+D12 -> 82 | F12: =IF(AND(B12=82,E12=82),"OK","CHECK") -> OK
A13: Indiana Pacers | B13: =COUNTIFS(Games_Raw!$K$2:$K$1232,"Yes",Games_Raw!$E$2:$E$1232,"Indiana Pacers")+COUNTIFS(Games_Raw!$K$2:$K$1232,"Yes",Games_Raw!$F$2:$F$1232,"Indiana Pacers") -> 82 | C13: =COUNTIFS(Games_Raw!$K$2:$K$1232,"Yes",Games_Raw!$I$2:$I$1232,"Indiana Pacers") -> 50 | D13: =COUNTIFS(Games_Raw!$K$2:$K$1232,"Yes",Games_Raw!$J$2:$J$1232,"Indiana Pacers") -> 32 | E13: =C13+D13 -> 82 | F13: =IF(AND(B13=82,E13=82),"OK","CHECK") -> OK
A14: LA Clippers | B14: =COUNTIFS(Games_Raw!$K$2:$K$1232,"Yes",Games_Raw!$E$2:$E$1232,"LA Clippers")+COUNTIFS(Games_Raw!$K$2:$K$1232,"Yes",Games_Raw!$F$2:$F$1232,"LA Clippers") -> 82 | C14: =COUNTIFS(Games_Raw!$K$2:$K$1232,"Yes",Games_Raw!$I$2:$I$1232,"LA Clippers") -> 50 | D14: =COUNTIFS(Games_Raw!$K$2:$K$1232,"Yes",Games_Raw!$J$2:$J$1232,"LA Clippers") -> 32 | E14: =C14+D14 -> 82 | F14: =IF(AND(B14=82,E14=82),"OK","CHECK") -> OK
A15: Los Angeles Lakers | B15: =COUNTIFS(Games_Raw!$K$2:$K$1232,"Yes",Games_Raw!$E$2:$E$1232,"Los Angeles Lakers")+COUNTIFS(Games_Raw!$K$2:$K$1232,"Yes",Games_Raw!$F$2:$F$1232,"Los Angeles Lakers") -> 82 | C15: =COUNTIFS(Games_Raw!$K$2:$K$1232,"Yes",Games_Raw!$I$2:$I$1232,"Los Angeles Lakers") -> 50 | D15: =COUNTIFS(Games_Raw!$K$2:$K$1232,"Yes",Games_Raw!$J$2:$J$1232,"Los Angeles Lakers") -> 32 | E15: =C15+D15 -> 82 | F15: =IF(AND(B15=82,E15=82),"OK","CHECK") -> OK
A16: Memphis Grizzlies | B16: =COUNTIFS(Games_Raw!$K$2:$K$1232,"Yes",Games_Raw!$E$2:$E$1232,"Memphis Grizzlies")+COUNTIFS(Games_Raw!$K$2:$K$1232,"Yes",Games_Raw!$F$2:$F$1232,"Memphis Grizzlies") -> 82 | C16: =COUNTIFS(Games_Raw!$K$2:$K$1232,"Yes",Games_Raw!$I$2:$I$1232,"Memphis Grizzlies") -> 48 | D16: =COUNTIFS(Games_Raw!$K$2:$K$1232,"Yes",Games_Raw!$J$2:$J$1232,"Memphis Grizzlies") -> 34 | E16: =C16+D16 -> 82 | F16: =IF(AND(B16=82,E16=82),"OK","CHECK") -> OK
A17: Miami Heat | B17: =COUNTIFS(Games_Raw!$K$2:$K$1232,"Yes",Games_Raw!$E$2:$E$1232,"Miami Heat")+COUNTIFS(Games_Raw!$K$2:$K$1232,"Yes",Games_Raw!$F$2:$F$1232,"Miami Heat") -> 82 | C17: =COUNTIFS(Games_Raw!$K$2:$K$1232,"Yes",Games_Raw!$I$2:$I$1232,"Miami Heat") -> 37 | D17: =COUNTIFS(Games_Raw!$K$2:$K$1232,"Yes",Games_Raw!$J$2:$J$1232,"Miami Heat") -> 45 | E17: =C17+D17 -> 82 | F17: =IF(AND(B17=82,E17=82),"OK","CHECK") -> OK
A18: Milwaukee Bucks | B18: =COUNTIFS(Games_Raw!$K$2:$K$1232,"Yes",Games_Raw!$E$2:$E$1232,"Milwaukee Bucks")+COUNTIFS(Games_Raw!$K$2:$K$1232,"Yes",Games_Raw!$F$2:$F$1232,"Milwaukee Bucks") -> 82 | C18: =COUNTIFS(Games_Raw!$K$2:$K$1232,"Yes",Games_Raw!$I$2:$I$1232,"Milwaukee Bucks") -> 48 | D18: =COUNTIFS(Games_Raw!$K$2:$K$1232,"Yes",Games_Raw!$J$2:$J$1232,"Milwaukee Bucks") -> 34 | E18: =C18+D18 -> 82 | F18: =IF(AND(B18=82,E18=82),"OK","CHECK") -> OK
A19: Minnesota Timberwolves | B19: =COUNTIFS(Games_Raw!$K$2:$K$1232,"Yes",Games_Raw!$E$2:$E$1232,"Minnesota Timberwolves")+COUNTIFS(Games_Raw!$K$2:$K$1232,"Yes",Games_Raw!$F$2:$F$1232,"Minnesota Timberwolves") -> 82 | C19: =COUNTIFS(Games_Raw!$K$2:$K$1232,"Yes",Games_Raw!$I$2:$I$1232,"Minnesota Timberwolves") -> 49 | D19: =COUNTIFS(Games_Raw!$K$2:$K$1232,"Yes",Games_Raw!$J$2:$J$1232,"Minnesota Timberwolves") -> 33 | E19: =C19+D19 -> 82 | F19: =IF(AND(B19=82,E19=82),"OK","CHECK") -> OK
A20: New Orleans Pelicans | B20: =COUNTIFS(Games_Raw!$K$2:$K$1232,"Yes",Games_Raw!$E$2:$E$1232,"New Orleans Pelicans")+COUNTIFS(Games_Raw!$K$2:$K$1232,"Yes",Games_Raw!$F$2:$F$1232,"New Orleans Pelicans") -> 82 | C20: =COUNTIFS(Games_Raw!$K$2:$K$1232,"Yes",Games_Raw!$I$2:$I$1232,"New Orleans Pelicans") -> 21 | D20: =COUNTIFS(Games_Raw!$K$2:$K$1232,"Yes",Games_Raw!$J$2:$J$1232,"New Orleans Pelicans") -> 61 | E20: =C20+D20 -> 82 | F20: =IF(AND(B20=82,E20=82),"OK","CHECK") -> OK
A21: New York Knicks | B21: =COUNTIFS(Games_Raw!$K$2:$K$1232,"Yes",Games_Raw!$E$2:$E$1232,"New York Knicks")+COUNTIFS(Games_Raw!$K$2:$K$1232,"Yes",Games_Raw!$F$2:$F$1232,"New York Knicks") -> 82 | C21: =COUNTIFS(Games_Raw!$K$2:$K$1232,"Yes",Games_Raw!$I$2:$I$1232,"New York Knicks") -> 51 | D21: =COUNTIFS(Games_Raw!$K$2:$K$1232,"Yes",Games_Raw!$J$2:$J$1232,"New York Knicks") -> 31 | E21: =C21+D21 -> 82 | F21: =IF(AND(B21=82,E21=82),"OK","CHECK") -> OK
A22: Oklahoma City Thunder | B22: =COUNTIFS(Games_Raw!$K$2:$K$1232,"Yes",Games_Raw!$E$2:$E$1232,"Oklahoma City Thunder")+COUNTIFS(Games_Raw!$K$2:$K$1232,"Yes",Games_Raw!$F$2:$F$1232,"Oklahoma City Thunder") -> 82 | C22: =COUNTIFS(Games_Raw!$K$2:$K$1232,"Yes",Games_Raw!$I$2:$I$1232,"Oklahoma City Thunder") -> 68 | D22: =COUNTIFS(Games_Raw!$K$2:$K$1232,"Yes",Games_Raw!$J$2:$J$1232,"Oklahoma City Thunder") -> 14 | E22: =C22+D22 -> 82 | F22: =IF(AND(B22=82,E22=82),"OK","CHECK") -> OK
A23: Orlando Magic | B23: =COUNTIFS(Games_Raw!$K$2:$K$1232,"Yes",Games_Raw!$E$2:$E$1232,"Orlando Magic")+COUNTIFS(Games_Raw!$K$2:$K$1232,"Yes",Games_Raw!$F$2:$F$1232,"Orlando Magic") -> 82 | C23: =COUNTIFS(Games_Raw!$K$2:$K$1232,"Yes",Games_Raw!$I$2:$I$1232,"Orlando Magic") -> 41 | D23: =COUNTIFS(Games_Raw!$K$2:$K$1232,"Yes",Games_Raw!$J$2:$J$1232,"Orlando Magic") -> 41 | E23: =C23+D23 -> 82 | F23: =IF(AND(B23=82,E23=82),"OK","CHECK") -> OK
A24: Philadelphia 76ers | B24: =COUNTIFS(Games_Raw!$K$2:$K$1232,"Yes",Games_Raw!$E$2:$E$1232,"Philadelphia 76ers")+COUNTIFS(Games_Raw!$K$2:$K$1232,"Yes",Games_Raw!$F$2:$F$1232,"Philadelphia 76ers") -> 82 | C24: =COUNTIFS(Games_Raw!$K$2:$K$1232,"Yes",Games_Raw!$I$2:$I$1232,"Philadelphia 76ers") -> 24 | D24: =COUNTIFS(Games_Raw!$K$2:$K$1232,"Yes",Games_Raw!$J$2:$J$1232,"Philadelphia 76ers") -> 58 | E24: =C24+D24 -> 82 | F24: =IF(AND(B24=82,E24=82),"OK","CHECK") -> OK
A25: Phoenix Suns | B25: =COUNTIFS(Games_Raw!$K$2:$K$1232,"Yes",Games_Raw!$E$2:$E$1232,"Phoenix Suns")+COUNTIFS(Games_Raw!$K$2:$K$1232,"Yes",Games_Raw!$F$2:$F$1232,"Phoenix Suns") -> 82 | C25: =COUNTIFS(Games_Raw!$K$2:$K$1232,"Yes",Games_Raw!$I$2:$I$1232,"Phoenix Suns") -> 36 | D25: =COUNTIFS(Games_Raw!$K$2:$K$1232,"Yes",Games_Raw!$J$2:$J$1232,"Phoenix Suns") -> 46 | E25: =C25+D25 -> 82 | F25: =IF(AND(B25=82,E25=82),"OK","CHECK") -> OK
A26: Portland Trail Blazers | B26: =COUNTIFS(Games_Raw!$K$2:$K$1232,"Yes",Games_Raw!$E$2:$E$1232,"Portland Trail Blazers")+COUNTIFS(Games_Raw!$K$2:$K$1232,"Yes",Games_Raw!$F$2:$F$1232,"Portland Trail Blazers") -> 82 | C26: =COUNTIFS(Games_Raw!$K$2:$K$1232,"Yes",Games_Raw!$I$2:$I$1232,"Portland Trail Blazers") -> 36 | D26: =COUNTIFS(Games_Raw!$K$2:$K$1232,"Yes",Games_Raw!$J$2:$J$1232,"Portland Trail Blazers") -> 46 | E26: =C26+D26 -> 82 | F26: =IF(AND(B26=82,E26=82),"OK","CHECK") -> OK
A27: Sacramento Kings | B27: =COUNTIFS(Games_Raw!$K$2:$K$1232,"Yes",Games_Raw!$E$2:$E$1232,"Sacramento Kings")+COUNTIFS(Games_Raw!$K$2:$K$1232,"Yes",Games_Raw!$F$2:$F$1232,"Sacramento Kings") -> 82 | C27: =COUNTIFS(Games_Raw!$K$2:$K$1232,"Yes",Games_Raw!$I$2:$I$1232,"Sacramento Kings") -> 40 | D27: =COUNTIFS(Games_Raw!$K$2:$K$1232,"Yes",Games_Raw!$J$2:$J$1232,"Sacramento Kings") -> 42 | E27: =C27+D27 -> 82 | F27: =IF(AND(B27=82,E27=82),"OK","CHECK") -> OK
A28: San Antonio Spurs | B28: =COUNTIFS(Games_Raw!$K$2:$K$1232,"Yes",Games_Raw!$E$2:$E$1232,"San Antonio Spurs")+COUNTIFS(Games_Raw!$K$2:$K$1232,"Yes",Games_Raw!$F$2:$F$1232,"San Antonio Spurs") -> 82 | C28: =COUNTIFS(Games_Raw!$K$2:$K$1232,"Yes",Games_Raw!$I$2:$I$1232,"San Antonio Spurs") -> 34 | D28: =COUNTIFS(Games_Raw!$K$2:$K$1232,"Yes",Games_Raw!$J$2:$J$1232,"San Antonio Spurs") -> 48 | E28: =C28+D28 -> 82 | F28: =IF(AND(B28=82,E28=82),"OK","CHECK") -> OK
A29: Toronto Raptors | B29: =COUNTIFS(Games_Raw!$K$2:$K$1232,"Yes",Games_Raw!$E$2:$E$1232,"Toronto Raptors")+COUNTIFS(Games_Raw!$K$2:$K$1232,"Yes",Games_Raw!$F$2:$F$1232,"Toronto Raptors") -> 82 | C29: =COUNTIFS(Games_Raw!$K$2:$K$1232,"Yes",Games_Raw!$I$2:$I$1232,"Toronto Raptors") -> 30 | D29: =COUNTIFS(Games_Raw!$K$2:$K$1232,"Yes",Games_Raw!$J$2:$J$1232,"Toronto Raptors") -> 52 | E29: =C29+D29 -> 82 | F29: =IF(AND(B29=82,E29=82),"OK","CHECK") -> OK
A30: Utah Jazz | B30: =COUNTIFS(Games_Raw!$K$2:$K$1232,"Yes",Games_Raw!$E$2:$E$1232,"Utah Jazz")+COUNTIFS(Games_Raw!$K$2:$K$1232,"Yes",Games_Raw!$F$2:$F$1232,"Utah Jazz") -> 82 | C30: =COUNTIFS(Games_Raw!$K$2:$K$1232,"Yes",Games_Raw!$I$2:$I$1232,"Utah Jazz") -> 17 | D30: =COUNTIFS(Games_Raw!$K$2:$K$1232,"Yes",Games_Raw!$J$2:$J$1232,"Utah Jazz") -> 65 | E30: =C30+D30 -> 82 | F30: =IF(AND(B30=82,E30=82),"OK","CHECK") -> OK
A31: Washington Wizards | B31: =COUNTIFS(Games_Raw!$K$2:$K$1232,"Yes",Games_Raw!$E$2:$E$1232,"Washington Wizards")+COUNTIFS(Games_Raw!$K$2:$K$1232,"Yes",Games_Raw!$F$2:$F$1232,"Washington Wizards") -> 82 | C31: =COUNTIFS(Games_Raw!$K$2:$K$1232,"Yes",Games_Raw!$I$2:$I$1232,"Washington Wizards") -> 18 | D31: =COUNTIFS(Games_Raw!$K$2:$K$1232,"Yes",Games_Raw!$J$2:$J$1232,"Washington Wizards") -> 64 | E31: =C31+D31 -> 82 | F31: =IF(AND(B31=82,E31=82),"OK","CHECK") -> OK

Sheet Detail
A1: Team | B1: Opponent | C1: Wins | D1: Losses | E1: Series | F1: Total Team Wins | G1: Total Team Losses
A2: Atlanta Hawks | B2: Boston Celtics | C2: =COUNTIFS(Games_Raw!$K$2:$K$1232,"Yes",Games_Raw!$I$2:$I$1232,A2,Games_Raw!$J$2:$J$1232,B2) -> 2 | D2: =COUNTIFS(Games_Raw!$K$2:$K$1232,"Yes",Games_Raw!$I$2:$I$1232,B2,Games_Raw!$J$2:$J$1232,A2) -> 1 | E2: =C2&"-"&D2 -> 2-1 | F2: =COUNTIFS(Games_Raw!$K$2:$K$1232,"Yes",Games_Raw!$I$2:$I$1232,A2) -> 40 | G2: =COUNTIFS(Games_Raw!$K$2:$K$1232,"Yes",Games_Raw!$J$2:$J$1232,A2) -> 42
A3: Atlanta Hawks | B3: Brooklyn Nets | C3: =COUNTIFS(Games_Raw!$K$2:$K$1232,"Yes",Games_Raw!$I$2:$I$1232,A3,Games_Raw!$J$2:$J$1232,B3) -> 2 | D3: =COUNTIFS(Games_Raw!$K$2:$K$1232,"Yes",Games_Raw!$I$2:$I$1232,B3,Games_Raw!$J$2:$J$1232,A3) -> 1 | E3: =C3&"-"&D3 -> 2-1 | F3: =COUNTIFS(Games_Raw!$K$2:$K$1232,"Yes",Games_Raw!$I$2:$I$1232,A3) -> 40 | G3: =COUNTIFS(Games_Raw!$K$2:$K$1232,"Yes",Games_Raw!$J$2:$J$1232,A3) -> 42
A4: Atlanta Hawks | B4: Charlotte Hornets | C4: =COUNTIFS(Games_Raw!$K$2:$K$1232,"Yes",Games_Raw!$I$2:$I$1232,A4,Games_Raw!$J$2:$J$1232,B4) -> 4 | D4: =COUNTIFS(Games_Raw!$K$2:$K$1232,"Yes",Games_Raw!$I$2:$I$1232,B4,Games_Raw!$J$2:$J$1232,A4) -> 0 | E4: =C4&"-"&D4 -> 4-0 | F4: =COUNTIFS(Games_Raw!$K$2:$K$1232,"Yes",Games_Raw!$I$2:$I$1232,A4) -> 40 | G4: =COUNTIFS(Games_Raw!$K$2:$K$1232,"Yes",Games_Raw!$J$2:$J$1232,A4) -> 42
A5: Atlanta Hawks | B5: Chicago Bulls | C5: =COUNTIFS(Games_Raw!$K$2:$K$1232,"Yes",Games_Raw!$I$2:$I$1232,A5,Games_Raw!$J$2:$J$1232,B5) -> 2 | D5: =COUNTIFS(Games_Raw!$K$2:$K$1232,"Yes",Games_Raw!$I$2:$I$1232,B5,Games_Raw!$J$2:$J$1232,A5) -> 2 | E5: =C5&"-"&D5 -> 2-2 | F5: =COUNTIFS(Games_Raw!$K$2:$K$1232,"Yes",Games_Raw!$I$2:$I$1232,A5) -> 40 | G5: =COUNTIFS(Games_Raw!$K$2:$K$1232,"Yes",Games_Raw!$J$2:$J$1232,A5) -> 42
A6: Atlanta Hawks | B6: Cleveland Cavaliers | C6: =COUNTIFS(Games_Raw!$K$2:$K$1232,"Yes",Games_Raw!$I$2:$I$1232,A6,Games_Raw!$J$2:$J$1232,B6) -> 2 | D6: =COUNTIFS(Games_Raw!$K$2:$K$1232,"Yes",Games_Raw!$I$2:$I$1232,B6,Games_Raw!$J$2:$J$1232,A6) -> 1 | E6: =C6&"-"&D6 -> 2-1 | F6: =COUNTIFS(Games_Raw!$K$2:$K$1232,"Yes",Games_Raw!$I$2:$I$1232,A6) -> 40 | G6: =COUNTIFS(Games_Raw!$K$2:$K$1232,"Yes",Games_Raw!$J$2:$J$1232,A6) -> 42
A7: Atlanta Hawks | B7: Dallas Mavericks | C7: =COUNTIFS(Games_Raw!$K$2:$K$1232,"Yes",Games_Raw!$I$2:$I$1232,A7,Games_Raw!$J$2:$J$1232,B7) -> 0 | D7: =COUNTIFS(Games_Raw!$K$2:$K$1232,"Yes",Games_Raw!$I$2:$I$1232,B7,Games_Raw!$J$2:$J$1232,A7) -> 2 | E7: =C7&"-"&D7 -> 0-2 | F7: =COUNTIFS(Games_Raw!$K$2:$K$1232,"Yes",Games_Raw!$I$2:$I$1232,A7) -> 40 | G7: =COUNTIFS(Games_Raw!$K$2:$K$1232,"Yes",Games_Raw!$J$2:$J$1232,A7) -> 42
A8: Atlanta Hawks | B8: Denver Nuggets | C8: =COUNTIFS(Games_Raw!$K$2:$K$1232,"Yes",Games_Raw!$I$2:$I$1232,A8,Games_Raw!$J$2:$J$1232,B8) -> 0 | D8: =COUNTIFS(Games_Raw!$K$2:$K$1232,"Yes",Games_Raw!$I$2:$I$1232,B8,Games_Raw!$J$2:$J$1232,A8) -> 2 | E8: =C8&"-"&D8 -> 0-2 | F8: =COUNTIFS(Games_Raw!$K$2:$K$1232,"Yes",Games_Raw!$I$2:$I$1232,A8) -> 40 | G8: =COUNTIFS(Games_Raw!$K$2:$K$1232,"Yes",Games_Raw!$J$2:$J$1232,A8) -> 42
A9: Atlanta Hawks | B9: Detroit Pistons | C9: =COUNTIFS(Games_Raw!$K$2:$K$1232,"Yes",Games_Raw!$I$2:$I$1232,A9,Games_Raw!$J$2:$J$1232,B9) -> 1 | D9: =COUNTIFS(Games_Raw!$K$2:$K$1232,"Yes",Games_Raw!$I$2:$I$1232,B9,Games_Raw!$J$2:$J$1232,A9) -> 3 | E9: =C9&"-"&D9 -> 1-3 | F9: =COUNTIFS(Games_Raw!$K$2:$K$1232,"Yes",Games_Raw!$I$2:$I$1232,A9) -> 40 | G9: =COUNTIFS(Games_Raw!$K$2:$K$1232,"Yes",Games_Raw!$J$2:$J$1232,A9) -> 42
A10: Atlanta Hawks | B10: Golden State Warriors | C10: =COUNTIFS(Games_Raw!$K$2:$K$1232,"Yes",Games_Raw!$I$2:$I$1232,A10,Games_Raw!$J$2:$J$1232,B10) -> 1 | D10: =COUNTIFS(Games_Raw!$K$2:$K$1232,"Yes",Games_Raw!$I$2:$I$1232,B10,Games_Raw!$J$2:$J$1232,A10) -> 1 | E10: =C10&"-"&D10 -> 1-1 | F10: =COUNTIFS(Games_Raw!$K$2:$K$1232,"Yes",Games_Raw!$I$2:$I$1232,A10) -> 40 | G10: =COUNTIFS(Games_Raw!$K$2:$K$1232,"Yes",Games_Raw!$J$2:$J$1232,A10) -> 42
A11: Atlanta Hawks | B11: Houston Rockets | C11: =COUNTIFS(Games_Raw!$K$2:$K$1232,"Yes",Games_Raw!$I$2:$I$1232,A11,Games_Raw!$J$2:$J$1232,B11) -> 0 | D11: =COUNTIFS(Games_Raw!$K$2:$K$1232,"Yes",Games_Raw!$I$2:$I$1232,B11,Games_Raw!$J$2:$J$1232,A11) -> 2 | E11: =C11&"-"&D11 -> 0-2 | F11: =COUNTIFS(Games_Raw!$K$2:$K$1232,"Yes",Games_Raw!$I$2:$I$1232,A11) -> 40 | G11: =COUNTIFS(Games_Raw!$K$2:$K$1232,"Yes",Games_Raw!$J$2:$J$1232,A11) -> 42
A12: Atlanta Hawks | B12: Indiana Pacers | C12: =COUNTIFS(Games_Raw!$K$2:$K$1232,"Yes",Games_Raw!$I$2:$I$1232,A12,Games_Raw!$J$2:$J$1232,B12) -> 2 | D12: =COUNTIFS(Games_Raw!$K$2:$K$1232,"Yes",Games_Raw!$I$2:$I$1232,B12,Games_Raw!$J$2:$J$1232,A12) -> 1 | E12: =C12&"-"&D12 -> 2-1 | F12: =COUNTIFS(Games_Raw!$K$2:$K$1232,"Yes",Games_Raw!$I$2:$I$1232,A12) -> 40 | G12: =COUNTIFS(Games_Raw!$K$2:$K$1232,"Yes",Games_Raw!$J$2:$J$1232,A12) -> 42
A13: Atlanta Hawks | B13: LA Clippers | C13: =COUNTIFS(Games_Raw!$K$2:$K$1232,"Yes",Games_Raw!$I$2:$I$1232,A13,Games_Raw!$J$2:$J$1232,B13) -> 0 | D13: =COUNTIFS(Games_Raw!$K$2:$K$1232,"Yes",Games_Raw!$I$2:$I$1232,B13,Games_Raw!$J$2:$J$1232,A13) -> 2 | E13: =C13&"-"&D13 -> 0-2 | F13: =COUNTIFS(Games_Raw!$K$2:$K$1232,"Yes",Games_Raw!$I$2:$I$1232,A13) -> 40 | G13: =COUNTIFS(Games_Raw!$K$2:$K$1232,"Yes",Games_Raw!$J$2:$J$1232,A13) -> 42
... A871: Washington Wizards | B871: Utah Jazz | C871: =COUNTIFS(Games_Raw!$K$2:$K$1232,"Yes",Games_Raw!$I$2:$I$1232,A871,Games_Raw!$J$2:$J$1232,B871) -> 1 | D871: =COUNTIFS(Games_Raw!$K$2:$K$1232,"Yes",Games_Raw!$I$2:$I$1232,B871,Games_Raw!$J$2:$J$1232,A871) -> 1 | E871: =C871&"-"&D871 -> 1-1 | F871: =COUNTIFS(Games_Raw!$K$2:$K$1232,"Yes",Games_Raw!$I$2:$I$1232,A871) -> 18 | G871: =COUNTIFS(Games_Raw!$K$2:$K$1232,"Yes",Games_Raw!$J$2:$J$1232,A871) -> 64

Sheet Wins_Matrix
A1: Wins vs Opponent
A2: Team \ Opponent | B2: Atlanta Hawks | C2: Boston Celtics | D2: Brooklyn Nets | E2: Charlotte Hornets | F2: Chicago Bulls | G2: Cleveland Cavaliers | H2: Dallas Mavericks | I2: Denver Nuggets | J2: Detroit Pistons | K2: Golden State Warriors | L2: Houston Rockets | M2: Indiana Pacers | N2: LA Clippers | O2: Los Angeles Lakers | P2: Memphis Grizzlies | Q2: Miami Heat | R2: Milwaukee Bucks | S2: Minnesota Timberwolves | T2: New Orleans Pelicans | U2: New York Knicks | V2: Oklahoma City Thunder | W2: Orlando Magic | X2: Philadelphia 76ers | Y2: Phoenix Suns | Z2: Portland Trail Blazers | AA2: Sacramento Kings | AB2: San Antonio Spurs | AC2: Toronto Raptors | AD2: Utah Jazz | AE2: Washington Wizards | AF2: Total
A3: Atlanta Hawks | B3: - | C3: =Detail!C2 -> 2 | D3: =Detail!C3 -> 2 | E3: =Detail!C4 -> 4 | F3: =Detail!C5 -> 2 | G3: =Detail!C6 -> 2 | H3: =Detail!C7 -> 0 | I3: =Detail!C8 -> 0 | J3: =Detail!C9 -> 1 | K3: =Detail!C10 -> 1 | L3: =Detail!C11 -> 0 | M3: =Detail!C12 -> 2 | N3: =Detail!C13 -> 0 | O3: =Detail!C14 -> 1 | P3: =Detail!C15 -> 1 | Q3: =Detail!C16 -> 2 | R3: =Detail!C17 -> 3 | S3: =Detail!C18 -> 1 | T3: =Detail!C19 -> 2 | U3: =Detail!C20 -> 2 | V3: =Detail!C21 -> 0 | W3: =Detail!C22 -> 2 | X3: =Detail!C23 -> 3 | Y3: =Detail!C24 -> 1 | Z3: =Detail!C25 -> 0 | AA3: =Detail!C26 -> 1 | AB3: =Detail!C27 -> 0 | AC3: =Detail!C28 -> 1 | AD3: =Detail!C29 -> 2 | AE3: =Detail!C30 -> 2 | AF3: =SUM(B3:AE3) -> 40
A4: Boston Celtics | B4: =Detail!C31 -> 1 | C4: - | D4: =Detail!C32 -> 4 | E4: =Detail!C33 -> 4 | F4: =Detail!C34 -> 3 | G4: =Detail!C35 -> 2 | H4: =Detail!C36 -> 1 | I4: =Detail!C37 -> 2 | J4: =Detail!C38 -> 3 | K4: =Detail!C39 -> 1 | L4: =Detail!C40 -> 1 | M4: =Detail!C41 -> 1 | N4: =Detail!C42 -> 2 | O4: =Detail!C43 -> 1 | P4: =Detail!C44 -> 1 | Q4: =Detail!C45 -> 3 | R4: =Detail!C46 -> 3 | S4: =Detail!C47 -> 2 | T4: =Detail!C48 -> 2 | U4: =Detail!C49 -> 4 | V4: =Detail!C50 -> 0 | W4: =Detail!C51 -> 1 | X4: =Detail!C52 -> 3 | Y4: =Detail!C53 -> 2 | Z4: =Detail!C54 -> 2 | AA4: =Detail!C55 -> 1 | AB4: =Detail!C56 -> 2 | AC4: =Detail!C57 -> 3 | AD4: =Detail!C58 -> 2 | AE4: =Detail!C59 -> 4 | AF4: =SUM(B4:AE4) -> 61
A5: Brooklyn Nets | B5: =Detail!C60 -> 1 | C5: =Detail!C61 -> 0 | D5: - | E5: =Detail!C62 -> 3 | F5: =Detail!C63 -> 1 | G5: =Detail!C64 -> 0 | H5: =Detail!C65 -> 1 | I5: =Detail!C66 -> 0 | J5: =Detail!C67 -> 0 | K5: =Detail!C68 -> 1 | L5: =Detail!C69 -> 2 | M5: =Detail!C70 -> 1 | N5: =Detail!C71 -> 0 | O5: =Detail!C72 -> 1 | P5: =Detail!C73 -> 2 | Q5: =Detail!C74 -> 1 | R5: =Detail!C75 -> 3 | S5: =Detail!C76 -> 0 | T5: =Detail!C77 -> 2 | U5: =Detail!C78 -> 0 | V5: =Detail!C79 -> 0 | W5: =Detail!C80 -> 0 | X5: =Detail!C81 -> 2 | Y5: =Detail!C82 -> 1 | Z5: =Detail!C83 -> 1 | AA5: =Detail!C84 -> 1 | AB5: =Detail!C85 -> 0 | AC5: =Detail!C86 -> 1 | AD5: =Detail!C87 -> 0 | AE5: =Detail!C88 -> 1 | AF5: =SUM(B5:AE5) -> 26
A6: Charlotte Hornets | B6: =Detail!C89 -> 0 | C6: =Detail!C90 -> 0 | D6: =Detail!C91 -> 1 | E6: - | F6: =Detail!C92 -> 1 | G6: =Detail!C93 -> 0 | H6: =Detail!C94 -> 1 | I6: =Detail!C95 -> 0 | J6: =Detail!C96 -> 2 | K6: =Detail!C97 -> 0 | L6: =Detail!C98 -> 1 | M6: =Detail!C99 -> 2 | N6: =Detail!C100 -> 0 | O6: =Detail!C101 -> 1 | P6: =Detail!C102 -> 0 | Q6: =Detail!C103 -> 1 | R6: =Detail!C104 -> 1 | S6: =Detail!C105 -> 0 | T6: =Detail!C106 -> 1 | U6: =Detail!C107 -> 1 | V6: =Detail!C108 -> 0 | W6: =Detail!C109 -> 0 | X6: =Detail!C110 -> 0 | Y6: =Detail!C111 -> 1 | Z6: =Detail!C112 -> 0 | AA6: =Detail!C113 -> 0 | AB6: =Detail!C114 -> 2 | AC6: =Detail!C115 -> 1 | AD6: =Detail!C116 -> 2 | AE6: =Detail!C117 -> 0 | AF6: =SUM(B6:AE6) -> 19
A7: Chicago Bulls | B7: =Detail!C118 -> 2 | C7: =Detail!C119 -> 1 | D7: =Detail!C120 -> 2 | E7: =Detail!C121 -> 3 | F7: - | G7: =Detail!C122 -> 0 | H7: =Detail!C123 -> 0 | I7: =Detail!C124 -> 2 | J7: =Detail!C125 -> 1 | K7: =Detail!C126 -> 0 | L7: =Detail!C127 -> 0 | M7: =Detail!C128 -> 1 | N7: =Detail!C129 -> 1 | O7: =Detail!C130 -> 2 | P7: =Detail!C131 -> 1 | Q7: =Detail!C132 -> 3 | R7: =Detail!C133 -> 2 | S7: =Detail!C134 -> 0 | T7: =Detail!C135 -> 0 | U7: =Detail!C136 -> 2 | V7: =Detail!C137 -> 0 | W7: =Detail!C138 -> 2 | X7: =Detail!C139 -> 2 | Y7: =Detail!C140 -> 0 | Z7: =Detail!C141 -> 1 | AA7: =Detail!C142 -> 1 | AB7: =Detail!C143 -> 2 | AC7: =Detail!C144 -> 4 | AD7: =Detail!C145 -> 1 | AE7: =Detail!C146 -> 3 | AF7: =SUM(B7:AE7) -> 39
A8: Cleveland Cavaliers | B8: =Detail!C147 -> 1 | C8: =Detail!C148 -> 2 | D8: =Detail!C149 -> 4 | E8: =Detail!C150 -> 4 | F8: =Detail!C151 -> 4 | G8: - | H8: =Detail!C152 -> 2 | I8: =Detail!C153 -> 2 | J8: =Detail!C154 -> 3 | K8: =Detail!C155 -> 2 | L8: =Detail!C156 -> 0 | M8: =Detail!C157 -> 1 | N8: =Detail!C158 -> 1 | O8: =Detail!C159 -> 2 | P8: =Detail!C160 -> 2 | Q8: =Detail!C161 -> 2 | R8: =Detail!C162 -> 4 | S8: =Detail!C163 -> 2 | T8: =Detail!C164 -> 2 | U8: =Detail!C165 -> 4 | V8: =Detail!C166 -> 1 | W8: =Detail!C167 -> 2 | X8: =Detail!C168 -> 2 | Y8: =Detail!C169 -> 1 | Z8: =Detail!C170 -> 2 | AA8: =Detail!C171 -> 0 | AB8: =Detail!C172 -> 2 | AC8: =Detail!C173 -> 4 | AD8: =Detail!C174 -> 2 | AE8: =Detail!C175 -> 4 | AF8: =SUM(B8:AE8) -> 64
A9: Dallas Mavericks | B9: =Detail!C176 -> 2 | C9: =Detail!C177 -> 1 | D9: =Detail!C178 -> 1 | E9: =Detail!C179 -> 1 | F9: =Detail!C180 -> 2 | G9: =Detail!C181 -> 0 | H9: - | I9: =Detail!C182 -> 1 | J9: =Detail!C183 -> 1 | K9: =Detail!C184 -> 2 | L9: =Detail!C185 -> 1 | M9: =Detail!C186 -> 0 | N9: =Detail!C187 -> 1 | O9: =Detail!C188 -> 1 | P9: =Detail!C189 -> 1 | Q9: =Detail!C190 -> 1 | R9: =Detail!C191 -> 0 | S9: =Detail!C192 -> 1 | T9: =Detail!C193 -> 3 | U9: =Detail!C194 -> 1 | V9: =Detail!C195 -> 3 | W9: =Detail!C196 -> 2 | X9: =Detail!C197 -> 0 | Y9: =Detail!C198 -> 1 | Z9: =Detail!C199 -> 3 | AA9: =Detail!C200 -> 0 | AB9: =Detail!C201 -> 3 | AC9: =Detail!C202 -> 2 | AD9: =Detail!C203 -> 2 | AE9: =Detail!C204 -> 2 | AF9: =SUM(B9:AE9) -> 39
A10: Denver Nuggets | B10: =Detail!C205 -> 2 | C10: =Detail!C206 -> 0 | D10: =Detail!C207 -> 2 | E10: =Detail!C208 -> 2 | F10: =Detail!C209 -> 0 | G10: =Detail!C210 -> 0 | H10: =Detail!C211 -> 3 | I10: - | J10: =Detail!C212 -> 2 | K10: =Detail!C213 -> 2 | L10: =Detail!C214 -> 2 | M10: =Detail!C215 -> 1 | N10: =Detail!C216 -> 2 | O10: =Detail!C217 -> 2 | P10: =Detail!C218 -> 2 | Q10: =Detail!C219 -> 2 | R10: =Detail!C220 -> 1 | S10: =Detail!C221 -> 0 | T10: =Detail!C222 -> 3 | U10: =Detail!C223 -> 0 | V10: =Detail!C224 -> 2 | W10: =Detail!C225 -> 2 | X10: =Detail!C226 -> 2 | Y10: =Detail!C227 -> 3 | Z10: =Detail!C228 -> 2 | AA10: =Detail!C229 -> 4 | AB10: =Detail!C230 -> 1 | AC10: =Detail!C231 -> 2 | AD10: =Detail!C232 -> 4 | AE10: =Detail!C233 -> 0 | AF10: =SUM(B10:AE10) -> 50
A11: Detroit Pistons | B11: =Detail!C234 -> 3 | C11: =Detail!C235 -> 1 | D11: =Detail!C236 -> 3 | E11: =Detail!C237 -> 2 | F11: =Detail!C238 -> 3 | G11: =Detail!C239 -> 1 | H11: =Detail!C240 -> 1 | I11: =Detail!C241 -> 0 | J11: - | K11: =Detail!C242 -> 0 | L11: =Detail!C243 -> 1 | M11: =Detail!C244 -> 1 | N11: =Detail!C245 -> 1 | O11: =Detail!C246 -> 2 | P11: =Detail!C247 -> 0 | Q11: =Detail!C248 -> 3 | R11: =Detail!C249 -> 0 | S11: =Detail!C250 -> 1 | T11: =Detail!C251 -> 2 | U11: =Detail!C252 -> 3 | V11: =Detail!C253 -> 0 | W11: =Detail!C254 -> 1 | X11: =Detail!C255 -> 2 | Y11: =Detail!C256 -> 1 | Z11: =Detail!C257 -> 2 | AA11: =Detail!C258 -> 1 | AB11: =Detail!C259 -> 2 | AC11: =Detail!C260 -> 4 | AD11: =Detail!C261 -> 1 | AE11: =Detail!C262 -> 2 | AF11: =SUM(B11:AE11) -> 44
A12: Golden State Warriors | B12: =Detail!C263 -> 1 | C12: =Detail!C264 -> 1 | D12: =Detail!C265 -> 1 | E12: =Detail!C266 -> 2 | F12: =Detail!C267 -> 2 | G12: =Detail!C268 -> 0 | H12: =Detail!C269 -> 2 | I12: =Detail!C270 -> 1 | J12: =Detail!C271 -> 2 | K12: - | L12: =Detail!C272 -> 3 | M12: =Detail!C273 -> 0 | N12: =Detail!C274 -> 0 | O12: =Detail!C275 -> 1 | P12: =Detail!C276 -> 3 | Q12: =Detail!C277 -> 0 | R12: =Detail!C278 -> 2 | S12: =Detail!C279 -> 3 | T12: =Detail!C280 -> 4 | U12: =Detail!C281 -> 2 | V12: =Detail!C282 -> 2 | W12: =Detail!C283 -> 2 | X12: =Detail!C284 -> 1 | Y12: =Detail!C285 -> 2 | Z12: =Detail!C286 -> 3 | AA12: =Detail!C287 -> 2 | AB12: =Detail!C288 -> 1 | AC12: =Detail!C289 -> 1 | AD12: =Detail!C290 -> 2 | AE12: =Detail!C291 -> 2 | AF12: =SUM(B12:AE12) -> 48
A13: Houston Rockets | B13: =Detail!C292 -> 2 | C13: =Detail!C293 -> 1 | D13: =Detail!C294 -> 0 | E13: =Detail!C295 -> 1 | F13: =Detail!C296 -> 2 | G13: =Detail!C297 -> 2 | H13: =Detail!C298 -> 3 | I13: =Detail!C299 -> 1 | J13: =Detail!C300 -> 1 | K13: =Detail!C301 -> 2 | L13: - | M13: =Detail!C302 -> 1 | N13: =Detail!C303 -> 3 | O13: =Detail!C304 -> 1 | P13: =Detail!C305 -> 3 | Q13: =Detail!C306 -> 1 | R13: =Detail!C307 -> 1 | S13: =Detail!C308 -> 2 | T13: =Detail!C309 -> 4 | U13: =Detail!C310 -> 1 | V13: =Detail!C311 -> 2 | W13: =Detail!C312 -> 2 | X13: =Detail!C313 -> 2 | Y13: =Detail!C314 -> 3 | Z13: =Detail!C315 -> 2 | AA13: =Detail!C316 -> 0 | AB13: =Detail!C317 -> 3 | AC13: =Detail!C318 -> 2 | AD13: =Detail!C319 -> 2 | AE13: =Detail!C320 -> 2 | AF13: =SUM(B13:AE13) -> 52
A14: Indiana Pacers | B14: =Detail!C321 -> 1 | C14: =Detail!C322 -> 2 | D14: =Detail!C323 -> 3 | E14: =Detail!C324 -> 1 | F14: =Detail!C325 -> 3 | G14: =Detail!C326 -> 3 | H14: =Detail!C327 -> 2 | I14: =Detail!C328 -> 1 | J14: =Detail!C329 -> 3 | K14: =Detail!C330 -> 2 | L14: =Detail!C331 -> 1 | M14: - | N14: =Detail!C332 -> 2 | O14: =Detail!C333 -> 0 | P14: =Detail!C334 -> 1 | Q14: =Detail!C335 -> 2 | R14: =Detail!C336 -> 1 | S14: =Detail!C337 -> 2 | T14: =Detail!C338 -> 2 | U14: =Detail!C339 -> 1 | V14: =Detail!C340 -> 0 | W14: =Detail!C341 -> 1 | X14: =Detail!C342 -> 3 | Y14: =Detail!C343 -> 2 | Z14: =Detail!C344 -> 1 | AA14: =Detail!C345 -> 2 | AB14: =Detail!C346 -> 1 | AC14: =Detail!C347 -> 1 | AD14: =Detail!C348 -> 2 | AE14: =Detail!C349 -> 4 | AF14: =SUM(B14:AE14) -> 50
A15: LA Clippers | B15: =Detail!C350 -> 2 | C15: =Detail!C351 -> 0 | D15: =Detail!C352 -> 2 | E15: =Detail!C353 -> 2 | F15: =Detail!C354 -> 1 | G15: =Detail!C355 -> 1 | H15: =Detail!C356 -> 3 | I15: =Detail!C357 -> 2 | J15: =Detail!C358 -> 1 | K15: =Detail!C359 -> 4 | L15: =Detail!C360 -> 1 | M15: =Detail!C361 -> 0 | N15: - | O15: =Detail!C362 -> 1 | P15: =Detail!C363 -> 3 | Q15: =Detail!C364 -> 2 | R15: =Detail!C365 -> 1 | S15: =Detail!C366 -> 0 | T15: =Detail!C367 -> 2 | U15: =Detail!C368 -> 2 | V15: =Detail!C369 -> 0 | W15: =Detail!C370 -> 2 | X15: =Detail!C371 -> 2 | Y15: =Detail!C372 -> 0 | Z15: =Detail!C373 -> 2 | AA15: =Detail!C374 -> 4 | AB15: =Detail!C375 -> 3 | AC15: =Detail!C376 -> 1 | AD15: =Detail!C377 -> 4 | AE15: =Detail!C378 -> 2 | AF15: =SUM(B15:AE15) -> 50
A16: Los Angeles Lakers | B16: =Detail!C379 -> 1 | C16: =Detail!C380 -> 1 | D16: =Detail!C381 -> 1 | E16: =Detail!C382 -> 1 | F16: =Detail!C383 -> 0 | G16: =Detail!C384 -> 0 | H16: =Detail!C385 -> 2 | I16: =Detail!C386 -> 2 | J16: =Detail!C387 -> 0 | K16: =Detail!C388 -> 3 | L16: =Detail!C389 -> 2 | M16: =Detail!C390 -> 2 | N16: =Detail!C391 -> 3 | O16: - | P16: =Detail!C392 -> 3 | Q16: =Detail!C393 -> 1 | R16: =Detail!C394 -> 0 | S16: =Detail!C395 -> 2 | T16: =Detail!C396 -> 3 | U16: =Detail!C397 -> 2 | V16: =Detail!C398 -> 1 | W16: =Detail!C399 -> 0 | X16: =Detail!C400 -> 1 | Y16: =Detail!C401 -> 2 | Z16: =Detail!C402 -> 3 | AA16: =Detail!C403 -> 4 | AB16: =Detail!C404 -> 3 | AC16: =Detail!C405 -> 2 | AD16: =Detail!C406 -> 3 | AE16: =Detail!C407 -> 2 | AF16: =SUM(B16:AE16) -> 50
A17: Memphis Grizzlies | B17: =Detail!C408 -> 1 | C17: =Detail!C409 -> 1 | D17: =Detail!C410 -> 1 | E17: =Detail!C411 -> 2 | F17: =Detail!C412 -> 1 | G17: =Detail!C413 -> 0 | H17: =Detail!C414 -> 3 | I17: =Detail!C415 -> 1 | J17: =Detail!C416 -> 2 | K17: =Detail!C417 -> 1 | L17: =Detail!C418 -> 1 | M17: =Detail!C419 -> 1 | N17: =Detail!C420 -> 0 | O17: =Detail!C421 -> 1 | P17: - | Q17: =Detail!C422 -> 2 | R17: =Detail!C423 -> 2 | S17: =Detail!C424 -> 2 | T17: =Detail!C425 -> 4 | U17: =Detail!C426 -> 0 | V17: =Detail!C427 -> 0 | W17: =Detail!C428 -> 2 | X17: =Detail!C429 -> 2 | Y17: =Detail!C430 -> 4 | Z17: =Detail!C431 -> 2 | AA17: =Detail!C432 -> 1 | AB17: =Detail!C433 -> 3 | AC17: =Detail!C434 -> 2 | AD17: =Detail!C435 -> 4 | AE17: =Detail!C436 -> 2 | AF17: =SUM(B17:AE17) -> 48
A18: Miami Heat | B18: =Detail!C437 -> 2 | C18: =Detail!C438 -> 1 | D18: =Detail!C439 -> 2 | E18: =Detail!C440 -> 3 | F18: =Detail!C441 -> 0 | G18: =Detail!C442 -> 1 | H18: =Detail!C443 -> 1 | I18: =Detail!C444 -> 0 | J18: =Detail!C445 -> 1 | K18: =Detail!C446 -> 2 | L18: =Detail!C447 -> 1 | M18: =Detail!C448 -> 2 | N18: =Detail!C449 -> 0 | O18: =Detail!C450 -> 1 | P18: =Detail!C451 -> 0 | Q18: - | R18: =Detail!C452 -> 0 | S18: =Detail!C453 -> 1 | T18: =Detail!C454 -> 2 | U18: =Detail!C455 -> 0 | V18: =Detail!C456 -> 0 | W18: =Detail!C457 -> 2 | X18: =Detail!C458 -> 4 | Y18: =Detail!C459 -> 1 | Z18: =Detail!C460 -> 1 | AA18: =Detail!C461 -> 0 | AB18: =Detail!C462 -> 2 | AC18: =Detail!C463 -> 3 | AD18: =Detail!C464 -> 1 | AE18: =Detail!C465 -> 3 | AF18: =SUM(B18:AE18) -> 37
A19: Milwaukee Bucks | B19: =Detail!C466 -> 2 | C19: =Detail!C467 -> 0 | D19: =Detail!C468 -> 1 | E19: =Detail!C469 -> 2 | F19: =Detail!C470 -> 2 | G19: =Detail!C471 -> 0 | H19: =Detail!C472 -> 2 | I19: =Detail!C473 -> 1 | J19: =Detail!C474 -> 4 | K19: =Detail!C475 -> 0 | L19: =Detail!C476 -> 1 | M19: =Detail!C477 -> 3 | N19: =Detail!C478 -> 1 | O19: =Detail!C479 -> 2 | P19: =Detail!C480 -> 0 | Q19: =Detail!C481 -> 4 | R19: - | S19: =Detail!C482 -> 2 | T19: =Detail!C483 -> 2 | U19: =Detail!C484 -> 0 | V19: =Detail!C485 -> 0 | W19: =Detail!C486 -> 3 | X19: =Detail!C487 -> 4 | Y19: =Detail!C488 -> 1 | Z19: =Detail!C489 -> 0 | AA19: =Detail!C490 -> 2 | AB19: =Detail!C491 -> 1 | AC19: =Detail!C492 -> 3 | AD19: =Detail!C493 -> 2 | AE19: =Detail!C494 -> 3 | AF19: =SUM(B19:AE19) -> 48
A20: Minnesota Timberwolves | B20: =Detail!C495 -> 1 | C20: =Detail!C496 -> 0 | D20: =Detail!C497 -> 2 | E20: =Detail!C498 -> 2 | F20: =Detail!C499 -> 2 | G20: =Detail!C500 -> 0 | H20: =Detail!C501 -> 2 | I20: =Detail!C502 -> 4 | J20: =Detail!C503 -> 1 | K20: =Detail!C504 -> 1 | L20: =Detail!C505 -> 2 | M20: =Detail!C506 -> 0 | N20: =Detail!C507 -> 3 | O20: =Detail!C508 -> 2 | P20: =Detail!C509 -> 1 | Q20: =Detail!C510 -> 1 | R20: =Detail!C511 -> 0 | S20: - | T20: =Detail!C512 -> 2 | U20: =Detail!C513 -> 1 | V20: =Detail!C514 -> 2 | W20: =Detail!C515 -> 2 | X20: =Detail!C516 -> 2 | Y20: =Detail!C517 -> 4 | Z20: =Detail!C518 -> 2 | AA20: =Detail!C519 -> 2 | AB20: =Detail!C520 -> 3 | AC20: =Detail!C521 -> 1 | AD20: =Detail!C522 -> 3 | AE20: =Detail!C523 -> 1 | AF20: =SUM(B20:AE20) -> 49
A21: New Orleans Pelicans | B21: =Detail!C524 -> 0 | C21: =Detail!C525 -> 0 | D21: =Detail!C526 -> 0 | E21: =Detail!C527 -> 1 | F21: =Detail!C528 -> 2 | G21: =Detail!C529 -> 0 | H21: =Detail!C530 -> 1 | I21: =Detail!C531 -> 1 | J21: =Detail!C532 -> 0 | K21: =Detail!C533 -> 0 | L21: =Detail!C534 -> 0 | M21: =Detail!C535 -> 1 | N21: =Detail!C536 -> 1 | O21: =Detail!C537 -> 0 | P21: =Detail!C538 -> 0 | Q21: =Detail!C539 -> 0 | R21: =Detail!C540 -> 0 | S21: =Detail!C541 -> 1 | T21: - | U21: =Detail!C542 -> 0 | V21: =Detail!C543 -> 0 | W21: =Detail!C544 -> 0 | X21: =Detail!C545 -> 2 | Y21: =Detail!C546 -> 2 | Z21: =Detail!C547 -> 1 | AA21: =Detail!C548 -> 1 | AB21: =Detail!C549 -> 2 | AC21: =Detail!C550 -> 0 | AD21: =Detail!C551 -> 3 | AE21: =Detail!C552 -> 2 | AF21: =SUM(B21:AE21) -> 21
A22: New York Knicks | B22: =Detail!C553 -> 3 | C22: =Detail!C554 -> 0 | D22: =Detail!C555 -> 4 | E22: =Detail!C556 -> 2 | F22: =Detail!C557 -> 1 | G22: =Detail!C558 -> 0 | H22: =Detail!C559 -> 1 | I22: =Detail!C560 -> 2 | J22: =Detail!C561 -> 1 | K22: =Detail!C562 -> 0 | L22: =Detail!C563 -> 1 | M22: =Detail!C564 -> 2 | N22: =Detail!C565 -> 0 | O22: =Detail!C566 -> 0 | P22: =Detail!C567 -> 2 | Q22: =Detail!C568 -> 3 | R22: =Detail!C569 -> 3 | S22: =Detail!C570 -> 1 | T22: =Detail!C571 -> 2 | U22: - | V22: =Detail!C572 -> 0 | W22: =Detail!C573 -> 3 | X22: =Detail!C574 -> 4 | Y22: =Detail!C575 -> 2 | Z22: =Detail!C576 -> 2 | AA22: =Detail!C577 -> 2 | AB22: =Detail!C578 -> 1 | AC22: =Detail!C579 -> 4 | AD22: =Detail!C580 -> 1 | AE22: =Detail!C581 -> 4 | AF22: =SUM(B22:AE22) -> 51
A23: Oklahoma City Thunder | B23: =Detail!C582 -> 2 | C23: =Detail!C583 -> 2 | D23: =Detail!C584 -> 2 | E23: =Detail!C585 -> 2 | F23: =Detail!C586 -> 2 | G23: =Detail!C587 -> 1 | H23: =Detail!C588 -> 1 | I23: =Detail!C589 -> 2 | J23: =Detail!C590 -> 2 | K23: =Detail!C591 -> 1 | L23: =Detail!C592 -> 3 | M23: =Detail!C593 -> 2 | N23: =Detail!C594 -> 4 | O23: =Detail!C595 -> 2 | P23: =Detail!C596 -> 4 | Q23: =Detail!C597 -> 2 | R23: =Detail!C598 -> 2 | S23: =Detail!C599 -> 2 | T23: =Detail!C600 -> 4 | U23: =Detail!C601 -> 2 | V23: - | W23: =Detail!C602 -> 2 | X23: =Detail!C603 -> 2 | Y23: =Detail!C604 -> 3 | Z23: =Detail!C605 -> 4 | AA23: =Detail!C606 -> 3 | AB23: =Detail!C607 -> 2 | AC23: =Detail!C608 -> 2 | AD23: =Detail!C609 -> 4 | AE23: =Detail!C610 -> 2 | AF23: =SUM(B23:AE23) -> 68
A24: Orlando Magic | B24: =Detail!C611 -> 2 | C24: =Detail!C612 -> 2 | D24: =Detail!C613 -> 4 | E24: =Detail!C614 -> 4 | F24: =Detail!C615 -> 1 | G24: =Detail!C616 -> 1 | H24: =Detail!C617 -> 0 | I24: =Detail!C618 -> 0 | J24: =Detail!C619 -> 2 | K24: =Detail!C620 -> 0 | L24: =Detail!C621 -> 0 | M24: =Detail!C622 -> 3 | N24: =Detail!C623 -> 0 | O24: =Detail!C624 -> 2 | P24: =Detail!C625 -> 0 | Q24: =Detail!C626 -> 2 | R24: =Detail!C627 -> 1 | S24: =Detail!C628 -> 0 | T24: =Detail!C629 -> 2 | U24: =Detail!C630 -> 1 | V24: =Detail!C631 -> 0 | W24: - | X24: =Detail!C632 -> 3 | Y24: =Detail!C633 -> 2 | Z24: =Detail!C634 -> 0 | AA24: =Detail!C635 -> 2 | AB24: =Detail!C636 -> 2 | AC24: =Detail!C637 -> 1 | AD24: =Detail!C638 -> 0 | AE24: =Detail!C639 -> 4 | AF24: =SUM(B24:AE24) -> 41
A25: Philadelphia 76ers | B25: =Detail!C640 -> 0 | C25: =Detail!C641 -> 1 | D25: =Detail!C642 -> 2 | E25: =Detail!C643 -> 4 | F25: =Detail!C644 -> 2 | G25: =Detail!C645 -> 1 | H25: =Detail!C646 -> 2 | I25: =Detail!C647 -> 0 | J25: =Detail!C648 -> 1 | K25: =Detail!C649 -> 1 | L25: =Detail!C650 -> 0 | M25: =Detail!C651 -> 1 | N25: =Detail!C652 -> 0 | O25: =Detail!C653 -> 1 | P25: =Detail!C654 -> 0 | Q25: =Detail!C655 -> 0 | R25: =Detail!C656 -> 0 | S25: =Detail!C657 -> 0 | T25: =Detail!C658 -> 0 | U25: =Detail!C659 -> 0 | V25: =Detail!C660 -> 0 | W25: =Detail!C661 -> 1 | X25: - | Y25: =Detail!C662 -> 0 | Z25: =Detail!C663 -> 1 | AA25: =Detail!C664 -> 1 | AB25: =Detail!C665 -> 1 | AC25: =Detail!C666 -> 0 | AD25: =Detail!C667 -> 2 | AE25: =Detail!C668 -> 2 | AF25: =SUM(B25:AE25) -> 24
A26: Phoenix Suns | B26: =Detail!C669 -> 1 | C26: =Detail!C670 -> 0 | D26: =Detail!C671 -> 1 | E26: =Detail!C672 -> 1 | F26: =Detail!C673 -> 2 | G26: =Detail!C674 -> 1 | H26: =Detail!C675 -> 3 | I26: =Detail!C676 -> 1 | J26: =Detail!C677 -> 1 | K26: =Detail!C678 -> 2 | L26: =Detail!C679 -> 0 | M26: =Detail!C680 -> 0 | N26: =Detail!C681 -> 4 | O26: =Detail!C682 -> 2 | P26: =Detail!C683 -> 0 | Q26: =Detail!C684 -> 1 | R26: =Detail!C685 -> 1 | S26: =Detail!C686 -> 0 | T26: =Detail!C687 -> 1 | U26: =Detail!C688 -> 0 | V26: =Detail!C689 -> 0 | W26: =Detail!C690 -> 0 | X26: =Detail!C691 -> 2 | Y26: - | Z26: =Detail!C692 -> 2 | AA26: =Detail!C693 -> 1 | AB26: =Detail!C694 -> 2 | AC26: =Detail!C695 -> 1 | AD26: =Detail!C696 -> 4 | AE26: =Detail!C697 -> 2 | AF26: =SUM(B26:AE26) -> 36
A27: Portland Trail Blazers | B27: =Detail!C698 -> 2 | C27: =Detail!C699 -> 0 | D27: =Detail!C700 -> 1 | E27: =Detail!C701 -> 2 | F27: =Detail!C702 -> 1 | G27: =Detail!C703 -> 0 | H27: =Detail!C704 -> 1 | I27: =Detail!C705 -> 2 | J27: =Detail!C706 -> 0 | K27: =Detail!C707 -> 0 | L27: =Detail!C708 -> 1 | M27: =Detail!C709 -> 1 | N27: =Detail!C710 -> 1 | O27: =Detail!C711 -> 1 | P27: =Detail!C712 -> 1 | Q27: =Detail!C713 -> 1 | R27: =Detail!C714 -> 2 | S27: =Detail!C715 -> 2 | T27: =Detail!C716 -> 3 | U27: =Detail!C717 -> 0 | V27: =Detail!C718 -> 0 | W27: =Detail!C719 -> 2 | X27: =Detail!C720 -> 1 | Y27: =Detail!C721 -> 2 | Z27: - | AA27: =Detail!C722 -> 2 | AB27: =Detail!C723 -> 1 | AC27: =Detail!C724 -> 2 | AD27: =Detail!C725 -> 2 | AE27: =Detail!C726 -> 2 | AF27: =SUM(B27:AE27) -> 36
A28: Sacramento Kings | B28: =Detail!C727 -> 1 | C28: =Detail!C728 -> 1 | D28: =Detail!C729 -> 1 | E28: =Detail!C730 -> 2 | F28: =Detail!C731 -> 1 | G28: =Detail!C732 -> 2 | H28: =Detail!C733 -> 3 | I28: =Detail!C734 -> 0 | J28: =Detail!C735 -> 1 | K28: =Detail!C736 -> 2 | L28: =Detail!C737 -> 3 | M28: =Detail!C738 -> 0 | N28: =Detail!C739 -> 0 | O28: =Detail!C740 -> 0 | P28: =Detail!C741 -> 2 | Q28: =Detail!C742 -> 2 | R28: =Detail!C743 -> 0 | S28: =Detail!C744 -> 2 | T28: =Detail!C745 -> 3 | U28: =Detail!C746 -> 0 | V28: =Detail!C747 -> 0 | W28: =Detail!C748 -> 0 | X28: =Detail!C749 -> 1 | Y28: =Detail!C750 -> 3 | Z28: =Detail!C751 -> 2 | AA28: - | AB28: =Detail!C752 -> 2 | AC28: =Detail!C753 -> 1 | AD28: =Detail!C754 -> 4 | AE28: =Detail!C755 -> 1 | AF28: =SUM(B28:AE28) -> 40
A29: San Antonio Spurs | B29: =Detail!C756 -> 2 | C29: =Detail!C757 -> 0 | D29: =Detail!C758 -> 2 | E29: =Detail!C759 -> 0 | F29: =Detail!C760 -> 0 | G29: =Detail!C761 -> 0 | H29: =Detail!C762 -> 1 | I29: =Detail!C763 -> 2 | J29: =Detail!C764 -> 0 | K29: =Detail!C765 -> 2 | L29: =Detail!C766 -> 1 | M29: =Detail!C767 -> 1 | N29: =Detail!C768 -> 1 | O29: =Detail!C769 -> 1 | P29: =Detail!C770 -> 1 | Q29: =Detail!C771 -> 0 | R29: =Detail!C772 -> 1 | S29: =Detail!C773 -> 1 | T29: =Detail!C774 -> 2 | U29: =Detail!C775 -> 1 | V29: =Detail!C776 -> 1 | W29: =Detail!C777 -> 0 | X29: =Detail!C778 -> 1 | Y29: =Detail!C779 -> 1 | Z29: =Detail!C780 -> 3 | AA29: =Detail!C781 -> 2 | AB29: - | AC29: =Detail!C782 -> 2 | AD29: =Detail!C783 -> 3 | AE29: =Detail!C784 -> 2 | AF29: =SUM(B29:AE29) -> 34
A30: Toronto Raptors | B30: =Detail!C785 -> 2 | C30: =Detail!C786 -> 1 | D30: =Detail!C787 -> 3 | E30: =Detail!C788 -> 2 | F30: =Detail!C789 -> 0 | G30: =Detail!C790 -> 0 | H30: =Detail!C791 -> 0 | I30: =Detail!C792 -> 0 | J30: =Detail!C793 -> 0 | K30: =Detail!C794 -> 1 | L30: =Detail!C795 -> 0 | M30: =Detail!C796 -> 2 | N30: =Detail!C797 -> 1 | O30: =Detail!C798 -> 0 | P30: =Detail!C799 -> 0 | Q30: =Detail!C800 -> 1 | R30: =Detail!C801 -> 0 | S30: =Detail!C802 -> 1 | T30: =Detail!C803 -> 2 | U30: =Detail!C804 -> 0 | V30: =Detail!C805 -> 0 | W30: =Detail!C806 -> 3 | X30: =Detail!C807 -> 4 | Y30: =Detail!C808 -> 1 | Z30: =Detail!C809 -> 0 | AA30: =Detail!C810 -> 1 | AB30: =Detail!C811 -> 0 | AC30: - | AD30: =Detail!C812 -> 2 | AE30: =Detail!C813 -> 3 | AF30: =SUM(B30:AE30) -> 30
A31: Utah Jazz | B31: =Detail!C814 -> 0 | C31: =Detail!C815 -> 0 | D31: =Detail!C816 -> 2 | E31: =Detail!C817 -> 0 | F31: =Detail!C818 -> 1 | G31: =Detail!C819 -> 0 | H31: =Detail!C820 -> 1 | I31: =Detail!C821 -> 0 | J31: =Detail!C822 -> 1 | K31: =Detail!C823 -> 1 | L31: =Detail!C824 -> 1 | M31: =Detail!C825 -> 0 | N31: =Detail!C826 -> 0 | O31: =Detail!C827 -> 1 | P31: =Detail!C828 -> 0 | Q31: =Detail!C829 -> 1 | R31: =Detail!C830 -> 0 | S31: =Detail!C831 -> 1 | T31: =Detail!C832 -> 0 | U31: =Detail!C833 -> 1 | V31: =Detail!C834 -> 0 | W31: =Detail!C835 -> 2 | X31: =Detail!C836 -> 0 | Y31: =Detail!C837 -> 0 | Z31: =Detail!C838 -> 2 | AA31: =Detail!C839 -> 0 | AB31: =Detail!C840 -> 1 | AC31: =Detail!C841 -> 0 | AD31: - | AE31: =Detail!C842 -> 1 | AF31: =SUM(B31:AE31) -> 17
A32: Washington Wizards | B32: =Detail!C843 -> 2 | C32: =Detail!C844 -> 0 | D32: =Detail!C845 -> 2 | E32: =Detail!C846 -> 4 | F32: =Detail!C847 -> 1 | G32: =Detail!C848 -> 0 | H32: =Detail!C849 -> 0 | I32: =Detail!C850 -> 2 | J32: =Detail!C851 -> 1 | K32: =Detail!C852 -> 0 | L32: =Detail!C853 -> 0 | M32: =Detail!C854 -> 0 | N32: =Detail!C855 -> 0 | O32: =Detail!C856 -> 0 | P32: =Detail!C857 -> 0 | Q32: =Detail!C858 -> 1 | R32: =Detail!C859 -> 0 | S32: =Detail!C860 -> 1 | T32: =Detail!C861 -> 0 | U32: =Detail!C862 -> 0 | V32: =Detail!C863 -> 0 | W32: =Detail!C864 -> 0 | X32: =Detail!C865 -> 1 | Y32: =Detail!C866 -> 0 | Z32: =Detail!C867 -> 0 | AA32: =Detail!C868 -> 1 | AB32: =Detail!C869 -> 0 | AC32: =Detail!C870 -> 1 | AD32: =Detail!C871 -> 1 | AE32: - | AF32: =SUM(B32:AE32) -> 18
A33: Total | B33: =SUM(B3:B32) -> 42 | C33: =SUM(C3:C32) -> 21 | D33: =SUM(D3:D32) -> 56 | E33: =SUM(E3:E32) -> 63 | F33: =SUM(F3:F32) -> 43 | G33: =SUM(G3:G32) -> 18 | H33: =SUM(H3:H32) -> 43 | I33: =SUM(I3:I32) -> 32 | ... AE33: =SUM(AE3:AE32) -> 64

Sheet Losses_Matrix
A1: Losses vs Opponent
A2: Team \ Opponent | B2: Atlanta Hawks | C2: Boston Celtics | D2: Brooklyn Nets | E2: Charlotte Hornets | F2: Chicago Bulls | G2: Cleveland Cavaliers | H2: Dallas Mavericks | I2: Denver Nuggets | J2: Detroit Pistons | K2: Golden State Warriors | L2: Houston Rockets | M2: Indiana Pacers | N2: LA Clippers | O2: Los Angeles Lakers | P2: Memphis Grizzlies | Q2: Miami Heat | R2: Milwaukee Bucks | S2: Minnesota Timberwolves | T2: New Orleans Pelicans | U2: New York Knicks | V2: Oklahoma City Thunder | W2: Orlando Magic | X2: Philadelphia 76ers | Y2: Phoenix Suns | Z2: Portland Trail Blazers | AA2: Sacramento Kings | AB2: San Antonio Spurs | AC2: Toronto Raptors | AD2: Utah Jazz | AE2: Washington Wizards | AF2: Total
A3: Atlanta Hawks | B3: - | C3: =Detail!D2 -> 1 | D3: =Detail!D3 -> 1 | E3: =Detail!D4 -> 0 | F3: =Detail!D5 -> 2 | G3: =Detail!D6 -> 1 | H3: =Detail!D7 -> 2 | I3: =Detail!D8 -> 2 | J3: =Detail!D9 -> 3 | K3: =Detail!D10 -> 1 | L3: =Detail!D11 -> 2 | M3: =Detail!D12 -> 1 | N3: =Detail!D13 -> 2 | O3: =Detail!D14 -> 1 | P3: =Detail!D15 -> 1 | Q3: =Detail!D16 -> 2 | R3: =Detail!D17 -> 2 | S3: =Detail!D18 -> 1 | T3: =Detail!D19 -> 0 | U3: =Detail!D20 -> 3 | V3: =Detail!D21 -> 2 | W3: =Detail!D22 -> 2 | X3: =Detail!D23 -> 0 | Y3: =Detail!D24 -> 1 | Z3: =Detail!D25 -> 2 | AA3: =Detail!D26 -> 1 | AB3: =Detail!D27 -> 2 | AC3: =Detail!D28 -> 2 | AD3: =Detail!D29 -> 0 | AE3: =Detail!D30 -> 2 | AF3: =SUM(B3:AE3) -> 42
A4: Boston Celtics | B4: =Detail!D31 -> 2 | C4: - | D4: =Detail!D32 -> 0 | E4: =Detail!D33 -> 0 | F4: =Detail!D34 -> 1 | G4: =Detail!D35 -> 2 | H4: =Detail!D36 -> 1 | I4: =Detail!D37 -> 0 | J4: =Detail!D38 -> 1 | K4: =Detail!D39 -> 1 | L4: =Detail!D40 -> 1 | M4: =Detail!D41 -> 2 | N4: =Detail!D42 -> 0 | O4: =Detail!D43 -> 1 | P4: =Detail!D44 -> 1 | Q4: =Detail!D45 -> 1 | R4: =Detail!D46 -> 0 | S4: =Detail!D47 -> 0 | T4: =Detail!D48 -> 0 | U4: =Detail!D49 -> 0 | V4: =Detail!D50 -> 2 | W4: =Detail!D51 -> 2 | X4: =Detail!D52 -> 1 | Y4: =Detail!D53 -> 0 | Z4: =Detail!D54 -> 0 | AA4: =Detail!D55 -> 1 | AB4: =Detail!D56 -> 0 | AC4: =Detail!D57 -> 1 | AD4: =Detail!D58 -> 0 | AE4: =Detail!D59 -> 0 | AF4: =SUM(B4:AE4) -> 21
A5: Brooklyn Nets | B5: =Detail!D60 -> 2 | C5: =Detail!D61 -> 4 | D5: - | E5: =Detail!D62 -> 1 | F5: =Detail!D63 -> 2 | G5: =Detail!D64 -> 4 | H5: =Detail!D65 -> 1 | I5: =Detail!D66 -> 2 | J5: =Detail!D67 -> 3 | K5: =Detail!D68 -> 1 | L5: =Detail!D69 -> 0 | M5: =Detail!D70 -> 3 | N5: =Detail!D71 -> 2 | O5: =Detail!D72 -> 1 | P5: =Detail!D73 -> 1 | Q5: =Detail!D74 -> 2 | R5: =Detail!D75 -> 1 | S5: =Detail!D76 -> 2 | T5: =Detail!D77 -> 0 | U5: =Detail!D78 -> 4 | V5: =Detail!D79 -> 2 | W5: =Detail!D80 -> 4 | X5: =Detail!D81 -> 2 | Y5: =Detail!D82 -> 1 | Z5: =Detail!D83 -> 1 | AA5: =Detail!D84 -> 1 | AB5: =Detail!D85 -> 2 | AC5: =Detail!D86 -> 3 | AD5: =Detail!D87 -> 2 | AE5: =Detail!D88 -> 2 | AF5: =SUM(B5:AE5) -> 56
A6: Charlotte Hornets | B6: =Detail!D89 -> 4 | C6: =Detail!D90 -> 4 | D6: =Detail!D91 -> 3 | E6: - | F6: =Detail!D92 -> 3 | G6: =Detail!D93 -> 4 | H6: =Detail!D94 -> 1 | I6: =Detail!D95 -> 2 | J6: =Detail!D96 -> 2 | K6: =Detail!D97 -> 2 | L6: =Detail!D98 -> 1 | M6: =Detail!D99 -> 1 | N6: =Detail!D100 -> 2 | O6: =Detail!D101 -> 1 | P6: =Detail!D102 -> 2 | Q6: =Detail!D103 -> 3 | R6: =Detail!D104 -> 2 | S6: =Detail!D105 -> 2 | T6: =Detail!D106 -> 1 | U6: =Detail!D107 -> 2 | V6: =Detail!D108 -> 2 | W6: =Detail!D109 -> 4 | X6: =Detail!D110 -> 4 | Y6: =Detail!D111 -> 1 | Z6: =Detail!D112 -> 2 | AA6: =Detail!D113 -> 2 | AB6: =Detail!D114 -> 0 | AC6: =Detail!D115 -> 2 | AD6: =Detail!D116 -> 0 | AE6: =Detail!D117 -> 4 | AF6: =SUM(B6:AE6) -> 63
A7: Chicago Bulls | B7: =Detail!D118 -> 2 | C7: =Detail!D119 -> 3 | D7: =Detail!D120 -> 1 | E7: =Detail!D121 -> 1 | F7: - | G7: =Detail!D122 -> 4 | H7: =Detail!D123 -> 2 | I7: =Detail!D124 -> 0 | J7: =Detail!D125 -> 3 | K7: =Detail!D126 -> 2 | L7: =Detail!D127 -> 2 | M7: =Detail!D128 -> 3 | N7: =Detail!D129 -> 1 | O7: =Detail!D130 -> 0 | P7: =Detail!D131 -> 1 | Q7: =Detail!D132 -> 0 | R7: =Detail!D133 -> 2 | S7: =Detail!D134 -> 2 | T7: =Detail!D135 -> 2 | U7: =Detail!D136 -> 1 | V7: =Detail!D137 -> 2 | W7: =Detail!D138 -> 1 | X7: =Detail!D139 -> 2 | Y7: =Detail!D140 -> 2 | Z7: =Detail!D141 -> 1 | AA7: =Detail!D142 -> 1 | AB7: =Detail!D143 -> 0 | AC7: =Detail!D144 -> 0 | AD7: =Detail!D145 -> 1 | AE7: =Detail!D146 -> 1 | AF7: =SUM(B7:AE7) -> 43
A8: Cleveland Cavaliers | B8: =Detail!D147 -> 2 | C8: =Detail!D148 -> 2 | D8: =Detail!D149 -> 0 | E8: =Detail!D150 -> 0 | F8: =Detail!D151 -> 0 | G8: - | H8: =Detail!D152 -> 0 | I8: =Detail!D153 -> 0 | J8: =Detail!D154 -> 1 | K8: =Detail!D155 -> 0 | L8: =Detail!D156 -> 2 | M8: =Detail!D157 -> 3 | N8: =Detail!D158 -> 1 | O8: =Detail!D159 -> 0 | P8: =Detail!D160 -> 0 | Q8: =Detail!D161 -> 1 | R8: =Detail!D162 -> 0 | S8: =Detail!D163 -> 0 | T8: =Detail!D164 -> 0 | U8: =Detail!D165 -> 0 | V8: =Detail!D166 -> 1 | W8: =Detail!D167 -> 1 | X8: =Detail!D168 -> 1 | Y8: =Detail!D169 -> 1 | Z8: =Detail!D170 -> 0 | AA8: =Detail!D171 -> 2 | AB8: =Detail!D172 -> 0 | AC8: =Detail!D173 -> 0 | AD8: =Detail!D174 -> 0 | AE8: =Detail!D175 -> 0 | AF8: =SUM(B8:AE8) -> 18
A9: Dallas Mavericks | B9: =Detail!D176 -> 0 | C9: =Detail!D177 -> 1 | D9: =Detail!D178 -> 1 | E9: =Detail!D179 -> 1 | F9: =Detail!D180 -> 0 | G9: =Detail!D181 -> 2 | H9: - | I9: =Detail!D182 -> 3 | J9: =Detail!D183 -> 1 | K9: =Detail!D184 -> 2 | L9: =Detail!D185 -> 3 | M9: =Detail!D186 -> 2 | N9: =Detail!D187 -> 3 | O9: =Detail!D188 -> 2 | P9: =Detail!D189 -> 3 | Q9: =Detail!D190 -> 1 | R9: =Detail!D191 -> 2 | S9: =Detail!D192 -> 2 | T9: =Detail!D193 -> 1 | U9: =Detail!D194 -> 1 | V9: =Detail!D195 -> 1 | W9: =Detail!D196 -> 0 | X9: =Detail!D197 -> 2 | Y9: =Detail!D198 -> 3 | Z9: =Detail!D199 -> 1 | AA9: =Detail!D200 -> 3 | AB9: =Detail!D201 -> 1 | AC9: =Detail!D202 -> 0 | AD9: =Detail!D203 -> 1 | AE9: =Detail!D204 -> 0 | AF9: =SUM(B9:AE9) -> 43
A10: Denver Nuggets | B10: =Detail!D205 -> 0 | C10: =Detail!D206 -> 2 | D10: =Detail!D207 -> 0 | E10: =Detail!D208 -> 0 | F10: =Detail!D209 -> 2 | G10: =Detail!D210 -> 2 | H10: =Detail!D211 -> 1 | I10: - | J10: =Detail!D212 -> 0 | K10: =Detail!D213 -> 1 | L10: =Detail!D214 -> 1 | M10: =Detail!D215 -> 1 | N10: =Detail!D216 -> 2 | O10: =Detail!D217 -> 2 | P10: =Detail!D218 -> 1 | Q10: =Detail!D219 -> 0 | R10: =Detail!D220 -> 1 | S10: =Detail!D221 -> 4 | T10: =Detail!D222 -> 1 | U10: =Detail!D223 -> 2 | V10: =Detail!D224 -> 2 | W10: =Detail!D225 -> 0 | X10: =Detail!D226 -> 0 | Y10: =Detail!D227 -> 1 | Z10: =Detail!D228 -> 2 | AA10: =Detail!D229 -> 0 | AB10: =Detail!D230 -> 2 | AC10: =Detail!D231 -> 0 | AD10: =Detail!D232 -> 0 | AE10: =Detail!D233 -> 2 | AF10: =SUM(B10:AE10) -> 32
A11: Detroit Pistons | B11: =Detail!D234 -> 1 | C11: =Detail!D235 -> 3 | D11: =Detail!D236 -> 0 | E11: =Detail!D237 -> 2 | F11: =Detail!D238 -> 1 | G11: =Detail!D239 -> 3 | H11: =Detail!D240 -> 1 | I11: =Detail!D241 -> 2 | J11: - | K11: =Detail!D242 -> 2 | L11: =Detail!D243 -> 1 | M11: =Detail!D244 -> 3 | N11: =Detail!D245 -> 1 | O11: =Detail!D246 -> 0 | P11: =Detail!D247 -> 2 | Q11: =Detail!D248 -> 1 | R11: =Detail!D249 -> 4 | S11: =Detail!D250 -> 1 | T11: =Detail!D251 -> 0 | U11: =Detail!D252 -> 1 | V11: =Detail!D253 -> 2 | W11: =Detail!D254 -> 2 | X11: =Detail!D255 -> 1 | Y11: =Detail!D256 -> 1 | Z11: =Detail!D257 -> 0 | AA11: =Detail!D258 -> 1 | AB11: =Detail!D259 -> 0 | AC11: =Detail!D260 -> 0 | AD11: =Detail!D261 -> 1 | AE11: =Detail!D262 -> 1 | AF11: =SUM(B11:AE11) -> 38
